Workbook

Sheet Summary
A2: Description | B2: UOM | C2: Value | D2: Actual Load KVA | E2: Remarks
A3: Service-1 Utility Sanction Load KVA | B3: KVA | C3: 4000 | D3: 2798
A5: Service-2 Utility Sanction Load KVA | B5: KVA | C5: 0 | D5: 0
A7: Customer contracted capacity | B7: KVA

Sheet NEW SUMMARY
A2: POWER SUMMARY | B2: Contract Demand | C2: Utility Consump | D2: Demand % | E2: IT Consump | F2: PUE
A3: Bangalore EB Service-1 | B3: 4000 | C3: 2798 | D3: =+C3/B3 -> 0.6995
B4: 0 | C4: 0 | D4: =+C4/B4 -> #DIV/0!
A5: TOTAL Bangalore-01 | B5: =B3+B4 -> 4000 | C5: =C3 -> 2798 | D5: =+C5/B5 -> 0.6995 | E5: 1574 | F5: =C5/E5 -> 1.7776366
A9: INVENTORY SUMMARY | B9: IT KW CAPACITY | E9: IT KW CONSUMPTION | G9: RACKSPACE CAPACITY
B10: Design | C10: Sold | D10: Available | E10: Consumed | F10: % of Sold | G10: Design | H10: Des - Losses | I10: Sold | J10: Available
A11: TOTAL Bangalore-01 | B11: 4860 | C11: ='Facility details '!O14 -> 2891 | D11: =+'NEW SUMMARY'!B11-'NEW SUMMARY'!C11 -> 1969 | E11: ='Facility details '!P14 -> 2124.6 | F11: =+E11/C11 -> 0.73490142 | G11: ='Facility details '!T11+'Facility details '!T12+'Facility details '!T13 -> 925 | H11: 2153 | I11: ='Facility details '!U11+'Facility details '!U12+'Facility details '!U13 -> 720 | J11: ='Facility details '!W11+'Facility details '!W12+'Facility details '!W13 -> 137
A12: BNG 01 by Floor:
A13: L1 | B13: 540 | C13: ='Facility details '!O11 -> 305 | D13: =+'NEW SUMMARY'!B13-'NEW SUMMARY'!C13 -> 235 | E13: ='Facility details '!P11 -> 91.5 | F13: =+E13/C13 -> 0.3 | G13: ='Facility details '!T11 -> 130 | H13: =+G13-'Facility details '!V11 -> 82 | I13: ='Facility details '!U11 -> 63 | J13: =+'NEW SUMMARY'!H13-'NEW SUMMARY'!I13 -> 19
A14: L3 | B14: 1620 | C14: ='Facility details '!O12 -> 1566 | D14: =+'NEW SUMMARY'!B14-'NEW SUMMARY'!C14 -> 54 | E14: ='Facility details '!P12 -> 1075.4 | F14: =+E14/C14 -> 0.68671775 | G14: ='Facility details '!T12 -> 540 | H14: =+G14-'Facility details '!V12 -> 520 | I14: ='Facility details '!U12 -> 402 | J14: =+'NEW SUMMARY'!H14-'NEW SUMMARY'!I14 -> 118
A15: L2 | B15: 1080 | C15: ='Facility details '!O13 -> 1020 | D15: =+'NEW SUMMARY'!B15-'NEW SUMMARY'!C15 -> 60 | E15: ='Facility details '!P13 -> 957.7 | F15: =+E15/C15 -> 0.93892157 | G15: ='Facility details '!T13 -> 255 | H15: =+G15-'Facility details '!V13 -> 255 | I15: ='Facility details '!U13 -> 255 | J15: =+'NEW SUMMARY'!H15-'NEW SUMMARY'!I15 -> 0

Sheet Facility details 
A1: Description | B1: Value | C1: Actual Load KVA
B2: As per the Sanction Letter | C2: Usage measured on 1of every month
A3: Utility Sanction Load KVA | B3: 4000 kVA | C3: 2573
A4: Utility Minimum Demand % | B4: 100 | C4: =2573/4000 -> 0.64325
A5: Utility Sanction Load KVA | B5: 0 | C5: 0 | V5: =13503 -> 13503
A6: Utility Minimum Demand % | B6: 0 | C6: 0
A9: Capacity Installed | B9: Transformer kW | C9: No of TX | D9: Catcher TX kW | E9: No. Of catcher | F9: Actual Load kW | G9: Generator kW | H9: No of DG | I9: Catcher DG kW | J9: No. Of catcher | K9: UPS kW | L9: UPS Config | M9: IT capacity Installed kW | N9: IT Power Sold in kW ( considering unity as PF) | O9: Allocated IT Power to customer ( Taking 50% as divercity factor for rated power customer ) | P9: IT kW Usage | Q9: Avaialble IT kW Design-Used | R9: Available IT kW Design-Sold | S9: Available IT kW Design-Sold ( Allocated capacity) | T9: MAX Rack Capacity | U9: Rack Space sold out | V9: Rack losss ( Cage+ non standard rack+ path) | W9: Available space | X9: Designed White Space ( in SQ FT) | Y9: Used White Space( in SQ FT) | Z9: Avaialble White Space ( in SQ FT)
B10: Mention the design kW capacity of Transformer | G10: Mention the design kW capacity of Generator | K10: Mention the design N capacity in kw in a N+N Configuration | M10: Installed including interfloor shared capacity | N10: Customer subscribed IT kW | O10: Allocated power | P10: Measured on 1st of every month | Q10: Measured on 1st of every month | R10: Measured on 1st of every month | S10: Measured on 1st of every month
A11: L1 | B11: 1600 | C11: 1 | D11: 1600 | E11: 1 | F11: 135.5 | G11: 1600 | H11: 1 | I11: 1600 | J11: 1 | K11: =600*0.9 -> 540 | L11: 300kVA X 2 No’s – Source A 300kVA X 2 no’s- Source B | M11: 540 | N11: 305 | O11: 305 | P11: 91.5 | Q11: =M11-P11 -> 448.5 | R11: =M11-N11 -> 235 | S11: =M11-O11 -> 235 | T11: 130 | U11: 63 | V11: 48 | W11: =T11-(U11+V11) -> 19 | X11: 3300 | Y11: 2857 | Z11: =X11-Y11 -> 443
A12: L3 | B12: 1600 | C12: 1 | F12: 1460 | G12: 1600 | H12: 1 | K12: 1620 | L12: 600kVA X 3 No’s – Source A 600kVA X 3 no’s- Source B | M12: 1620 | N12: 2106.5 | O12: 1566 | P12: 1075.4 | Q12: =M12-P12 -> 544.6 | R12: =M12-N12 -> -486.5 | S12: =M12-O12 -> 54 | T12: 540 | U12: 402 | V12: 20 | W12: =T12-(U12+V12) -> 118 | X12: 13820 | Y12: 9844 | Z12: =X12-Y12 -> 3976
A13: L2 | B13: 1800 | C13: 1 | D13: 1800 | E13: 1 | F13: 823 | G13: 1800 | H13: 1 | I13: 1800 | J13: 1 | K13: 1080 | L13: 600kVA X 2 No’s – Source A 600kVA X 2 no’s- Source B | M13: 1080 | N13: 1020 | O13: 1020 | P13: 957.7 | Q13: =M13-P13 -> 122.3 | R13: =M13-N13 -> 60 | S13: =M13-O13 -> 60 | T13: 255 | U13: 255 | V13: 0 | W13: =T13-(U13+V13) -> 0 | X13: 6120 | Y13: 6120 | Z13: =X13-Y13 -> 0
A14: Total | K14: =SUM(K11:K13) -> 3240 | M14: =SUM(M11:M13) -> 3240 | N14: =SUM(N11:N13) -> 3431.5 | O14: =SUM(O11:O13) -> 2891 | P14: =SUM(P11:P13) -> 2124.6 | Q14: =SUM(Q11:Q13) -> 1115.4 | R14: =SUM(R11:R13) -> -191.5 | S14: =SUM(S11:S13) -> 349 | T14: =SUM(T11:T13) -> 925 | ... Z14: =SUM(Z11:Z13) -> 4419

Sheet Customer details
T1: Divisification | V1: 0.5 | W1: Rated to Consumed | Z1: =#REF! -> #REF! | AB1: Actual PUE | AC1: =#REF! -> #REF! | AD1: Actual Unit Rate: | AE1: =#REF! -> #REF! | AF1: =+AC1*(AE1*(30.5*24-AH1)+AH1*20) -> #REF! | AG1: Genset Hr/Mo | AH1: 5
E2: Billing Model | G2: Space | P2: Power Capacity | AB2: Power Usage | AG2: Seating Space | AO2: Revenue (Monthly ) | AV2: Contract Information
A3: Floor | B3: Floor / Module | C3: Customer Name | D3: RHS/SH | E3: Power Subscription Model (Rated/Subscribed) | F3: Power Usage Model (Bundled / Metered) | G3: Subscription Mode | H3: Caged /Uncaged | I3: UoM | J3: Subscription | K3: In Use | L3: Yet to be given/ | M3: Billed | N3: Reserved Capacity if any (Non-Billable) | O3: Per Unit rate (MRC) | P3: Subscription Model | Q3: UoM | R3: Total Capacity Purchased | S3: Capacity in Use | T3: Capacity to be given | U3: Reserved Capacity if any | V3: Subscribed Capacity to be given in KW | W3: "Allocated" Capacity in KW | X3: DC NW Infra | Y3: Usage in KW | Z3: Billable Additional Capacity | AA3: Additional Capacity Charges (MRC) | AB3: Usage Model | AC3: Multiplier | AD3: Unit rate Model (Fixed/Variable) | AE3: Unit Rate (per KW-HR) | AF3: No Of Units (KW-HR/ Month | AG3: Subscription Model | AH3: UoM | AI3: Subscription | AJ3: In Use | AK3: Yet to be given | AL3: Billed | AM3: Reserved Capacity if any | AN3: Per Unit rate | AO3: Space revenue including capacity | AP3: Additional Capacity Revenue | AQ3: Power Usage revenue | AR3: Seating Space | AS3: Any Other Items | AT3: Total Revenue | AU3: Billing Frequency | AV3: Sales Order ref No | AW3: Contract Start Date | AX3: Term of Contract (No of Years) | AY3: Current Expiry Date | AZ3: Remarks if any | BA3: Cross connect
A4: L1 | B4: L1 | C4: Axis bank | D4: No | E4: Subscribed | F4: Metered | G4: Rack | H4: Caged | I4: =IF(G4="Rack","No of Racks",(IF(G4="Space","Sq Ft","U Space"))) -> No of Racks | J4: 50 | K4: 50 | L4: =J4-K4 -> 0 | M4: =J4 -> 50 | N4: =J4-M4 -> 0 | O4: =316000/12 -> 26333.333 | P4: =E4 -> Subscribed | Q4: kVA | R4: 305 | S4: =AF4/672 -> 63.639211 | T4: =R4-S4 -> 241.36079 | U4: 0 | V4: =IF(T4<=0,0,(IF(P4="Rated",(T4+U4)*$V$1,(T4+U4)))) -> 241.36079 | W4: =IF(P4="Rated",R4*$V$1,R4) -> 305 | X4: =S4 -> 63.639211 | Y4: =S4 -> 63.639211 | Z4: =T4*-1 -> -241.36079 | AB4: Metered | AC4: 1.6 | AD4: Variable | AF4: 42765.55 | AG4: No of Seats | AH4: No of seats | AI4: 5 | AJ4: 5 | AK4: =AI4-AJ4 -> 0 | AL4: =AI4 -> 5 | AM4: 0 | AO4: =O4*M4 -> 1316666.7 | AQ4: =AF4*AE4*AC4 -> 0 | AR4: =AN4*AL4 -> 0 | AT4: =SUBTOTAL(9,AO4:AS4) -> 1316666.7
A5: L2 | B5: L2 | C5: Union Bank | D5: No | E5: Subscribed | F5: Metered | G5: Rack | H5: Caged | I5: =IF(G5="Rack","No of Racks",(IF(G5="Space","Sq Ft","U Space"))) -> No of Racks | J5: 255 | K5: 255 | L5: =J5-K5 -> 0 | M5: =J5 -> 255 | N5: =J5-M5 -> 0 | O5: =((280000)+(81840))/12 -> 30153.333 | P5: =E5 -> Subscribed | Q5: KVA | R5: 1020 | S5: =AF5/672 -> 530.03112 | T5: =R5-S5 -> 489.96888 | U5: 0 | V5: =IF(T5<=0,0,(IF(P5="Rated",(T5+U5)*$V$1,(T5+U5)))) -> 489.96888 | W5: =IF(P5="Rated",R5*$V$1,R5) -> 1020 | X5: =S5 -> 530.03112 | Y5: =S5 -> 530.03112 | Z5: =T5*-1 -> -489.96888 | AB5: Metered | AC5: 1.75 | AD5: Fixed | AF5: 356180.91 | AG5: No of Seats | AH5: No of seats | AI5: 28 | AJ5: 28 | AK5: =AI5-AJ5 -> 0 | AL5: =AI5 -> 28 | AM5: 0 | AN5: 4112 | AO5: =O5*M5 -> 7689100 | AQ5: =AF5*AE5*AC5 -> 0 | AR5: =AN5*AL5 -> 115136 | AS5: 875306 | AT5: =SUBTOTAL(9,AO5:AS5) -> 8679542
A6: L3 | B6: DC-3 | C6: Yes bank | D6: No | E6: Subscribed | F6: Metered | G6: Rack | H6: Caged | I6: =IF(G6="Rack","No of Racks",(IF(G6="Space","Sq Ft","U Space"))) -> No of Racks | J6: 55 | K6: 55 | L6: =J6-K6 -> 0 | M6: =J6 -> 55 | N6: =J6-M6 -> 0 | O6: 38896 | P6: =E6 -> Subscribed | Q6: KVA | R6: 452 | S6: =AF6/672 -> 173.07908 | T6: =R6-S6 -> 278.92092 | U6: 0 | V6: =IF(T6<=0,0,(IF(P6="Rated",(T6+U6)*$V$1,(T6+U6)))) -> 278.92092 | W6: =IF(P6="Rated",R6*$V$1,R6) -> 452 | X6: =S6 -> 173.07908 | Y6: =S6 -> 173.07908 | Z6: =T6*-1 -> -278.92092 | AB6: Metered | AC6: 1.8 | AF6: 116309.14 | AG6: No of Seats | AH6: No of seats | AI6: 8 | AJ6: 8 | AK6: =AI6-AJ6 -> 0 | AL6: =AI6 -> 8 | AM6: 0 | AO6: =O6*M6 -> 2139280 | AQ6: =AF6*AE6*AC6 -> 0 | AR6: =AN6*AL6 -> 0 | AT6: =SUBTOTAL(9,AO6:AS6) -> 2139280
A7: L3 | B7: DC-3 | C7: UST Global | D7: yes | E7: Subscribed | F7: Metered | G7: Rack | H7: Uncaged | I7: =IF(G7="Rack","No of Racks",(IF(G7="Space","Sq Ft","U Space"))) -> No of Racks | J7: 5 | K7: 5 | L7: =J7-K7 -> 0 | M7: =J7 -> 5 | N7: =J7-M7 -> 0 | O7: =1232624/12/5 -> 20543.733 | P7: =E7 -> Subscribed | Q7: KVA | R7: 45 | S7: =AF7/672 -> 17.058185 | T7: =R7-S7 -> 27.941815 | U7: 0 | V7: =IF(T7<=0,0,(IF(P7="Rated",(T7+U7)*$V$1,(T7+U7)))) -> 27.941815 | W7: =IF(P7="Rated",R7*$V$1,R7) -> 45 | X7: =S7 -> 17.058185 | Y7: =S7 -> 17.058185 | Z7: =T7*-1 -> -27.941815 | AB7: Metered | AC7: 1.8 | AF7: 11463.1 | AG7: No of Seats | AH7: No of seats | AI7: 0 | AJ7: 0 | AK7: =AI7-AJ7 -> 0 | AL7: =AI7 -> 0 | AM7: 0 | AO7: =O7*M7 -> 102718.67 | AQ7: =AF7*AE7*AC7 -> 0 | AR7: =AN7*AL7 -> 0 | AT7: =SUBTOTAL(9,AO7:AS7) -> 102718.67
A8: L3 | B8: DC-3 | C8: Data vision software solutions pvt ltd | D8: yes | E8: Rated | F8: Bundled | G8: Rack | H8: Uncaged | I8: =IF(G8="Rack","No of Racks",(IF(G8="Space","Sq Ft","U Space"))) -> No of Racks | J8: 1 | K8: 1 | L8: =J8-K8 -> 0 | M8: =J8 -> 1 | N8: =J8-M8 -> 0 | P8: =E8 -> Rated | Q8: KVA | R8: 12 | S8: 11.61 | T8: =R8-S8 -> 0.39 | U8: 0 | V8: =IF(T8<=0,0,(IF(P8="Rated",(T8+U8)*$V$1,(T8+U8)))) -> 0.195 | W8: =IF(P8="Rated",R8*$V$1,R8) -> 6 | X8: =S8 -> 11.61 | Y8: =S8 -> 11.61 | Z8: =T8*-1 -> -0.39 | AA8: =90000/12 -> 7500 | AB8: Rated | AC8: 1.8 | AG8: No of Seats | AH8: No of seats | AI8: 0 | AJ8: 0 | AK8: =AI8-AJ8 -> 0 | AL8: =AI8 -> 0 | AM8: 0 | AO8: =O8*M8 -> 0 | AQ8: =AF8*AE8*AC8 -> 0 | AR8: =AN8*AL8 -> 0 | AT8: =SUBTOTAL(9,AO8:AS8) -> 0
A9: L3 | B9: DC-2 | C9: The Oriental Insurance Company Limited | D9: No | E9: Subscribed | F9: Metered | G9: Space | H9: Caged | I9: =IF(G9="Rack","No of Racks",(IF(G9="Space","Sq Ft","U Space"))) -> Sq Ft | J9: 600 | K9: 600 | L9: =J9-K9 -> 0 | M9: =J9 -> 600 | N9: =J9-M9 -> 0 | O9: 736 | P9: =E9 -> Subscribed | Q9: KVA | R9: 60 | S9: =AF9/672 -> 58.063289 | T9: =R9-S9 -> 1.9367113 | U9: 0 | V9: =IF(T9<=0,0,(IF(P9="Rated",(T9+U9)*$V$1,(T9+U9)))) -> 1.9367113 | W9: =IF(P9="Rated",R9*$V$1,R9) -> 60 | X9: =S9 -> 58.063289 | Y9: =S9 -> 58.063289 | Z9: =T9*-1 -> -1.9367113 | AB9: Metered | AC9: 1.8 | AF9: 39018.53 | AG9: No of Seats | AH9: No of seats | AI9: 10 | AJ9: 10 | AK9: =AI9-AJ9 -> 0 | AL9: =AI9 -> 10 | AM9: 0 | AO9: =O9*M9 -> 441600 | AQ9: =AF9*AE9*AC9 -> 0 | AR9: =AN9*AL9 -> 0 | AT9: =SUBTOTAL(9,AO9:AS9) -> 441600
A10: L3 | B10: DC-2 | C10: AGRICULTURE INSURANCE COMPANY OF INDIA LIMITED | D10: No | E10: Subscribed | F10: Metered | G10: Rack | H10: Uncaged | I10: =IF(G10="Rack","No of Racks",(IF(G10="Space","Sq Ft","U Space"))) -> No of Racks | J10: 14 | K10: 14 | L10: =J10-K10 -> 0 | M10: =J10 -> 14 | N10: =J10-M10 -> 0 | O10: =160000/12 -> 13333.333 | P10: =E10 -> Subscribed | Q10: KVA | R10: 102.5 | S10: =AF10/672 -> 26.249747 | T10: =R10-S10 -> 76.250253 | U10: 0 | V10: =IF(T10<=0,0,(IF(P10="Rated",(T10+U10)*$V$1,(T10+U10)))) -> 76.250253 | W10: =IF(P10="Rated",R10*$V$1,R10) -> 102.5 | X10: =S10 -> 26.249747 | Y10: =S10 -> 26.249747 | Z10: =T10*-1 -> -76.250253 | AB10: Metered | AC10: 1.8 | AF10: 17639.83 | AG10: No of Seats | AH10: No of seats | AI10: 3 | AJ10: 3 | AK10: =AI10-AJ10 -> 0 | AL10: =AI10 -> 3 | AM10: 0 | AO10: =O10*M10 -> 186666.67 | AQ10: =AF10*AE10*AC10 -> 0 | AR10: =AN10*AL10 -> 0 | AT10: =SUBTOTAL(9,AO10:AS10) -> 186666.67
A11: L3 | B11: DC-2 | C11: Polestar | D11: No | E11: Subscribed | F11: Metered | G11: Rack | H11: Caged | I11: =IF(G11="Rack","No of Racks",(IF(G11="Space","Sq Ft","U Space"))) -> No of Racks | J11: 5 | K11: 5 | L11: =J11-K11 -> 0 | M11: =J11 -> 5 | N11: =J11-M11 -> 0 | O11: 46250 | P11: =E11 -> Subscribed | Q11: KVA | R11: 12.5 | S11: =AF11/672 -> 10.33558 | T11: =R11-S11 -> 2.1644196 | U11: 0 | V11: =IF(T11<=0,0,(IF(P11="Rated",(T11+U11)*$V$1,(T11+U11)))) -> 2.1644196 | W11: =IF(P11="Rated",R11*$V$1,R11) -> 12.5 | X11: =S11 -> 10.33558 | Y11: =S11 -> 10.33558 | Z11: =T11*-1 -> -2.1644196 | AA11: =80000/12 -> 6666.6667 | AB11: Metered | AC11: 1.8 | AF11: 6945.51 | AG11: No of Seats | AH11: No of seats | AI11: 1 | AJ11: 1 | AK11: =AI11-AJ11 -> 0 | AL11: =AI11 -> 1 | AM11: 0 | AO11: =O11*M11 -> 231250 | AQ11: =AF11*AE11*AC11 -> 0 | AR11: =AN11*AL11 -> 0 | AT11: =SUBTOTAL(9,AO11:AS11) -> 231250
A12: L3 | B12: DC-2 | C12: New India Assurance Co. Ltd. | D12: No | E12: Subscribed | F12: Metered | G12: Rack | H12: Caged | I12: =IF(G12="Rack","No of Racks",(IF(G12="Space","Sq Ft","U Space"))) -> No of Racks | J12: 18 | K12: 18 | L12: =J12-K12 -> 0 | M12: =J12 -> 18 | N12: =J12-M12 -> 0 | O12: =3200004/12/18 -> 14814.833 | P12: =E12 -> Subscribed | Q12: KVA | R12: 88 | S12: =AF12/672 -> 68.001563 | T12: =R12-S12 -> 19.998437 | U12: 0 | V12: =IF(T12<=0,0,(IF(P12="Rated",(T12+U12)*$V$1,(T12+U12)))) -> 19.998437 | W12: =IF(P12="Rated",R12*$V$1,R12) -> 88 | X12: =S12 -> 68.001563 | Y12: =S12 -> 68.001563 | Z12: =T12*-1 -> -19.998437 | AB12: Metered | AC12: 1.8 | AF12: 45697.05 | AG12: No of Seats | AH12: No of seats | AI12: 3 | AJ12: 3 | AK12: =AI12-AJ12 -> 0 | AL12: =AI12 -> 3 | AM12: 0 | AO12: =O12*M12 -> 266667 | AQ12: =AF12*AE12*AC12 -> 0 | AR12: =AN12*AL12 -> 0 | AT12: =SUBTOTAL(9,AO12:AS12) -> 266667
A13: L3 | B13: DC-2 | C13: Torrent Power | D13: yes | E13: Subscribed | F13: Metered | G13: Rack | H13: Uncaged | I13: =IF(G13="Rack","No of Racks",(IF(G13="Space","Sq Ft","U Space"))) -> No of Racks | J13: 4 | K13: 4 | L13: =J13-K13 -> 0 | M13: =J13 -> 4 | N13: =J13-M13 -> 0 | O13: =776000/12/2 -> 32333.333 | P13: =E13 -> Subscribed | Q13: KVA | R13: 19 | S13: =AF13/672 -> 13.320952 | T13: =R13-S13 -> 5.6790476 | U13: 0 | V13: =IF(T13<=0,0,(IF(P13="Rated",(T13+U13)*$V$1,(T13+U13)))) -> 5.6790476 | W13: =IF(P13="Rated",R13*$V$1,R13) -> 19 | X13: =S13 -> 13.320952 | Y13: =S13 -> 13.320952 | Z13: =T13*-1 -> -5.6790476 | AB13: Metered | AC13: 1.8 | AF13: 8951.68 | AG13: No of Seats | AH13: No of seats | AI13: 0 | AJ13: 0 | AK13: =AI13-AJ13 -> 0 | AL13: =AI13 -> 0 | AM13: 0 | AO13: =O13*M13 -> 129333.33 | AQ13: =AF13*AE13*AC13 -> 0 | AR13: =AN13*AL13 -> 0 | AT13: =SUBTOTAL(9,AO13:AS13) -> 129333.33
A14: L3 | B14: DC-2 | C14: LIC HOUSING FINANCE LTD | D14: yes | E14: Subscribed | F14: Metered | G14: Rack | H14: Caged | I14: =IF(G14="Rack","No of Racks",(IF(G14="Space","Sq Ft","U Space"))) -> No of Racks | J14: 10 | K14: 10 | L14: =J14-K14 -> 0 | M14: =J14 -> 10 | N14: =J14-M14 -> 0 | O14: =4484415/12/10 -> 37370.125 | P14: =E14 -> Subscribed | Q14: KVA | R14: 30 | S14: =AF14/672 -> 13.092113 | T14: =R14-S14 -> 16.907887 | U14: 0 | V14: =IF(T14<=0,0,(IF(P14="Rated",(T14+U14)*$V$1,(T14+U14)))) -> 16.907887 | W14: =IF(P14="Rated",R14*$V$1,R14) -> 30 | X14: =S14 -> 13.092113 | Y14: =S14 -> 13.092113 | Z14: =T14*-1 -> -16.907887 | AB14: Metered | AC14: 1.8 | AF14: 8797.9 | AG14: No of Seats | AH14: No of seats | AI14: 1 | AJ14: 1 | AK14: =AI14-AJ14 -> 0 | AL14: =AI14 -> 1 | AM14: 0 | AO14: =O14*M14 -> 373701.25 | AQ14: =AF14*AE14*AC14 -> 0 | AR14: =AN14*AL14 -> 0 | AT14: =SUBTOTAL(9,AO14:AS14) -> 373701.25
A15: L3 | B15: DC-2 | C15: Avenue Supermart (Dmart) | D15: yes | E15: Rated | F15: Bundled | G15: Rack | H15: Uncaged | I15: =IF(G15="Rack","No of Racks",(IF(G15="Space","Sq Ft","U Space"))) -> No of Racks | J15: 10 | K15: 10 | L15: =J15-K15 -> 0 | M15: =J15 -> 10 | N15: =J15-M15 -> 0 | O15: =(3280006+90000)/12/6 -> 46805.639 | P15: =E15 -> Rated | Q15: KVA | R15: 83 | S15: 72.47 | T15: =R15-S15 -> 10.53 | U15: 0 | V15: =IF(T15<=0,0,(IF(P15="Rated",(T15+U15)*$V$1,(T15+U15)))) -> 5.265 | W15: =IF(P15="Rated",R15*$V$1,R15) -> 41.5 | X15: =S15 -> 72.47 | Y15: =S15 -> 72.47 | Z15: =T15*-1 -> -10.53 | AA15: =90000/12 -> 7500 | AB15: Rated | AC15: 1.8 | AG15: No of Seats | AH15: No of seats | AI15: 0 | AJ15: 0 | AK15: =AI15-AJ15 -> 0 | AL15: =AI15 -> 0 | AM15: 0 | AO15: =O15*M15 -> 468056.39 | AQ15: =AF15*AE15*AC15 -> 0 | AR15: =AN15*AL15 -> 0 | AT15: =SUBTOTAL(9,AO15:AS15) -> 468056.39
A16: L3 | B16: DC-2 | C16: Aviva | D16: No | E16: Rated | F16: Bundled | G16: Rack | H16: Caged | I16: =IF(G16="Rack","No of Racks",(IF(G16="Space","Sq Ft","U Space"))) -> No of Racks | J16: 6 | K16: 6 | L16: =J16-K16 -> 0 | M16: =J16 -> 6 | N16: =J16-M16 -> 0 | O16: =4113270/12/6 -> 57128.75 | P16: =E16 -> Rated | Q16: KVA | R16: 36 | S16: 23.46 | T16: =R16-S16 -> 12.54 | U16: 0 | V16: =IF(T16<=0,0,(IF(P16="Rated",(T16+U16)*$V$1,(T16+U16)))) -> 6.27 | W16: =IF(P16="Rated",R16*$V$1,R16) -> 18 | X16: =S16 -> 23.46 | Y16: =S16 -> 23.46 | Z16: =T16*-1 -> -12.54 | AB16: Rated | AC16: 1.8 | AG16: No of Seats | AH16: No of seats | AI16: 1 | AJ16: 1 | AK16: =AI16-AJ16 -> 0 | AL16: =AI16 -> 1 | AM16: 0 | AO16: =O16*M16 -> 342772.5 | AQ16: =AF16*AE16*AC16 -> 0 | AR16: =AN16*AL16 -> 0 | AT16: =SUBTOTAL(9,AO16:AS16) -> 342772.5
A17: L3 | B17: DC-2 | C17: HITPA | D17: yes | E17: Rated | F17: Bundled | G17: Rack | H17: Caged | I17: =IF(G17="Rack","No of Racks",(IF(G17="Space","Sq Ft","U Space"))) -> No of Racks | J17: 7 | K17: 7 | L17: =J17-K17 -> 0 | M17: =J17 -> 7 | N17: =J17-M17 -> 0 | O17: =4620000/7/12 -> 55000 | P17: =E17 -> Rated | Q17: KVA | R17: 45 | S17: 23.18 | T17: =R17-S17 -> 21.82 | U17: 0 | V17: =IF(T17<=0,0,(IF(P17="Rated",(T17+U17)*$V$1,(T17+U17)))) -> 10.91 | W17: =IF(P17="Rated",R17*$V$1,R17) -> 22.5 | X17: =S17 -> 23.18 | Y17: =S17 -> 23.18 | Z17: =T17*-1 -> -21.82 | AA17: =90000/12 -> 7500 | AB17: Rated | AC17: 1.8 | AG17: No of Seats | AH17: No of seats | AI17: 0 | AJ17: 0 | AK17: =AI17-AJ17 -> 0 | AL17: =AI17 -> 0 | AM17: 0 | AO17: =O17*M17 -> 385000 | AQ17: =AF17*AE17*AC17 -> 0 | AR17: =AN17*AL17 -> 0 | AT17: =SUBTOTAL(9,AO17:AS17) -> 385000
A18: L3 | B18: DC-2 | C18: Stock holding corporation of India | D18: No | E18: Subscribed | F18: Metered | G18: Rack | H18: Caged | I18: =IF(G18="Rack","No of Racks",(IF(G18="Space","Sq Ft","U Space"))) -> No of Racks | J18: 13 | K18: 13 | L18: =J18-K18 -> 0 | M18: =J18 -> 13 | N18: =J18-M18 -> 0 | O18: =598991/12 -> 49915.917 | P18: =E18 -> Subscribed | Q18: KW | R18: 42 | S18: =AF18/672 -> 23.768155 | T18: =R18-S18 -> 18.231845 | U18: 0 | V18: =IF(T18<=0,0,(IF(P18="Rated",(T18+U18)*$V$1,(T18+U18)))) -> 18.231845 | W18: =IF(P18="Rated",R18*$V$1,R18) -> 42 | X18: =S18 -> 23.768155 | Y18: =S18 -> 23.768155 | Z18: =T18*-1 -> -18.231845 | AB18: Metered | AC18: 1.8 | AF18: 15972.2 | AG18: No of Seats | AH18: No of seats | AI18: 5 | AJ18: 5 | AK18: =AI18-AJ18 -> 0 | AL18: =AI18 -> 5 | AM18: 0 | AO18: =O18*M18 -> 648906.92 | AQ18: =AF18*AE18*AC18 -> 0 | AR18: =AN18*AL18 -> 0 | AT18: =SUBTOTAL(9,AO18:AS18) -> 648906.92
A19: L3 | B19: DC-2 | C19: SIMPLE TELECOM PVT LTD | D19: yes | E19: Subscribed | F19: Metered | G19: Rack | H19: Uncaged | I19: =IF(G19="Rack","No of Racks",(IF(G19="Space","Sq Ft","U Space"))) -> No of Racks | J19: 1 | K19: 1 | L19: =J19-K19 -> 0 | M19: =J19 -> 1 | N19: =J19-M19 -> 0 | O19: =210000/12 -> 17500 | P19: =E19 -> Subscribed | Q19: KW | R19: 2.5 | S19: =AF19/672 -> 0.84166667 | T19: =R19-S19 -> 1.6583333 | U19: 0 | V19: =IF(T19<=0,0,(IF(P19="Rated",(T19+U19)*$V$1,(T19+U19)))) -> 1.6583333 | W19: =IF(P19="Rated",R19*$V$1,R19) -> 2.5 | X19: =S19 -> 0.84166667 | Y19: =S19 -> 0.84166667 | Z19: =T19*-1 -> -1.6583333 | AB19: Metered | AC19: 1.8 | AF19: 565.6 | AG19: No of Seats | AH19: No of seats | AI19: 0 | AJ19: 0 | AK19: =AI19-AJ19 -> 0 | AL19: =AI19 -> 0 | AM19: 0 | AO19: =O19*M19 -> 17500 | AQ19: =AF19*AE19*AC19 -> 0 | AR19: =AN19*AL19 -> 0 | AT19: =SUBTOTAL(9,AO19:AS19) -> 17500
A20: L3 | B20: DC-1 | C20: Vishal Megamart | D20: yes | E20: Subscribed | F20: Metered | G20: Rack | H20: Uncaged | I20: =IF(G20="Rack","No of Racks",(IF(G20="Space","Sq Ft","U Space"))) -> No of Racks | J20: 8 | K20: 8 | L20: =J20-K20 -> 0 | M20: =J20 -> 8 | N20: =J20-M20 -> 0 | O20: =850000/12/4 -> 17708.333 | P20: =E20 -> Subscribed | Q20: KW | R20: 32.5 | S20: =AF20/672 -> 27.698199 | T20: =R20-S20 -> 4.8018006 | U20: 0 | V20: =IF(T20<=0,0,(IF(P20="Rated",(T20+U20)*$V$1,(T20+U20)))) -> 4.8018006 | W20: =IF(P20="Rated",R20*$V$1,R20) -> 32.5 | X20: =S20 -> 27.698199 | Y20: =S20 -> 27.698199 | Z20: =T20*-1 -> -4.8018006 | AB20: Metered | AC20: 1.8 | AF20: 18613.19 | AG20: No of Seats | AH20: No of seats | AI20: 0 | AJ20: 0 | AK20: =AI20-AJ20 -> 0 | AL20: =AI20 -> 0 | AM20: 0 | AO20: =O20*M20 -> 141666.67 | AQ20: =AF20*AE20*AC20 -> 0 | AR20: =AN20*AL20 -> 0 | AT20: =SUBTOTAL(9,AO20:AS20) -> 141666.67
A21: L3 | B21: DC-1 | C21: MEIKO CLEAN SOLUTIONS (INDIA) PRIVATE LIMITED | D21: yes | E21: Subscribed | F21: Metered | G21: Rack | H21: Uncaged | I21: =IF(G21="Rack","No of Racks",(IF(G21="Space","Sq Ft","U Space"))) -> No of Racks | J21: 1 | K21: 1 | L21: =J21-K21 -> 0 | M21: =J21 -> 1 | N21: =J21-M21 -> 0 | P21: =E21 -> Subscribed | Q21: KVA | R21: 3 | S21: =AF21/672 -> 2.2065327 | T21: =R21-S21 -> 0.79346726 | U21: 0 | V21: =IF(T21<=0,0,(IF(P21="Rated",(T21+U21)*$V$1,(T21+U21)))) -> 0.79346726 | W21: =IF(P21="Rated",R21*$V$1,R21) -> 3 | X21: =S21 -> 2.2065327 | Y21: =S21 -> 2.2065327 | Z21: =T21*-1 -> -0.79346726 | AB21: Metered | AC21: 1.8 | AF21: 1482.79 | AG21: No of Seats | AH21: No of seats | AI21: 0 | AJ21: 0 | AK21: =AI21-AJ21 -> 0 | AL21: =AI21 -> 0 | AM21: 0 | AO21: =O21*M21 -> 0 | AQ21: =AF21*AE21*AC21 -> 0 | AR21: =AN21*AL21 -> 0 | AT21: =SUBTOTAL(9,AO21:AS21) -> 0
A22: L3 | B22: DC-1 | C22: CONTAQUE CLOUD PVT LTD | D22: yes | E22: Rated | F22: Bundled | G22: U space | H22: Uncaged | I22: =IF(G22="Rack","No of Racks",(IF(G22="Space","Sq Ft","U Space"))) -> U Space | J22: 21 | K22: 21 | L22: =J22-K22 -> 0 | M22: =J22 -> 21 | N22: =J22-M22 -> 0 | P22: =E22 -> Rated | Q22: KW | R22: 4 | S22: 4.29 | T22: =R22-S22 -> -0.29 | U22: 0 | V22: =IF(T22<=0,0,(IF(P22="Rated",(T22+U22)*$V$1,(T22+U22)))) -> 0 | W22: =IF(P22="Rated",R22*$V$1,R22) -> 2 | X22: =S22 -> 4.29 | Y22: =S22 -> 4.29 | Z22: =T22*-1 -> 0.29 | AB22: Rated | AC22: 1.8 | AG22: No of Seats | AH22: No of seats | AI22: 0 | AJ22: 0 | AK22: =AI22-AJ22 -> 0 | AL22: =AI22 -> 0 | AM22: 0 | AO22: =O22*M22 -> 0 | AQ22: =AF22*AE22*AC22 -> 0 | AR22: =AN22*AL22 -> 0 | AT22: =SUBTOTAL(9,AO22:AS22) -> 0
A23: L3 | B23: DC-1 | C23: CONTAQUE CLOUD PVT LTD | D23: yes | E23: Subscribed | F23: Metered | G23: Rack | H23: Uncaged | I23: =IF(G23="Rack","No of Racks",(IF(G23="Space","Sq Ft","U Space"))) -> No of Racks | J23: 1 | K23: 1 | L23: =J23-K23 -> 0 | M23: =J23 -> 1 | N23: =J23-M23 -> 0 | P23: =E23 -> Subscribed | Q23: KW | R23: 3 | S23: =AF23/672 -> 1.8181994 | T23: =R23-S23 -> 1.1818006 | U23: 0 | V23: =IF(T23<=0,0,(IF(P23="Rated",(T23+U23)*$V$1,(T23+U23)))) -> 1.1818006 | W23: =IF(P23="Rated",R23*$V$1,R23) -> 3 | X23: =S23 -> 1.8181994 | Y23: =S23 -> 1.8181994 | Z23: =T23*-1 -> -1.1818006 | AB23: Metered | AC23: 1.8 | AF23: 1221.83 | AG23: No of Seats | AH23: No of seats | AI23: 0 | AJ23: 0 | AK23: =AI23-AJ23 -> 0 | AL23: =AI23 -> 0 | AM23: 0 | AO23: =O23*M23 -> 0 | AQ23: =AF23*AE23*AC23 -> 0 | AR23: =AN23*AL23 -> 0 | AT23: =SUBTOTAL(9,AO23:AS23) -> 0
A24: L3 | B24: DC-1 | C24: CLINISYS INDIA PRIVATE LIMITED | D24: yes | E24: Subscribed | F24: Metered | G24: Rack | H24: Uncaged | I24: =IF(G24="Rack","No of Racks",(IF(G24="Space","Sq Ft","U Space"))) -> No of Racks | J24: 2 | K24: 2 | L24: =J24-K24 -> 0 | M24: =J24 -> 2 | N24: =J24-M24 -> 0 | P24: =E24 -> Subscribed | Q24: KW | R24: 7 | S24: =AF24/672 -> 4.9216815 | T24: =R24-S24 -> 2.0783185 | U24: 0 | V24: =IF(T24<=0,0,(IF(P24="Rated",(T24+U24)*$V$1,(T24+U24)))) -> 2.0783185 | W24: =IF(P24="Rated",R24*$V$1,R24) -> 7 | X24: =S24 -> 4.9216815 | Y24: =S24 -> 4.9216815 | Z24: =T24*-1 -> -2.0783185 | AB24: Metered | AC24: 1.8 | AF24: 3307.37 | AG24: No of Seats | AH24: No of seats | AI24: 0 | AJ24: 0 | AK24: =AI24-AJ24 -> 0 | AL24: =AI24 -> 0 | AM24: 0 | AO24: =O24*M24 -> 0 | AQ24: =AF24*AE24*AC24 -> 0 | AR24: =AN24*AL24 -> 0 | AT24: =SUBTOTAL(9,AO24:AS24) -> 0
A25: L3 | B25: DC-1 | C25: BAJAJ FINANCE LTD | D25: No | E25: Subscribed | F25: Metered | G25: Rack | H25: Caged | I25: =IF(G25="Rack","No of Racks",(IF(G25="Space","Sq Ft","U Space"))) -> No of Racks | J25: 5 | K25: 5 | L25: =J25-K25 -> 0 | M25: =J25 -> 5 | N25: =J25-M25 -> 0 | O25: =12237/12 -> 1019.75 | P25: =E25 -> Subscribed | Q25: KVA | R25: 30 | S25: =AF25/672 -> 16.492515 | T25: =R25-S25 -> 13.507485 | U25: 0 | V25: =IF(T25<=0,0,(IF(P25="Rated",(T25+U25)*$V$1,(T25+U25)))) -> 13.507485 | W25: =IF(P25="Rated",R25*$V$1,R25) -> 30 | X25: =S25 -> 16.492515 | Y25: =S25 -> 16.492515 | Z25: =T25*-1 -> -13.507485 | AB25: Metered | AC25: 1.8 | AF25: 11082.97 | AG25: No of Seats | AH25: No of seats | AI25: 1 | AJ25: 1 | AK25: =AI25-AJ25 -> 0 | AL25: =AI25 -> 1 | AM25: 0 | AO25: =O25*M25 -> 5098.75 | AQ25: =AF25*AE25*AC25 -> 0 | AR25: =AN25*AL25 -> 0 | AT25: =SUBTOTAL(9,AO25:AS25) -> 5098.75
A26: L3 | B26: DC-1 | C26: UNISYS INDIA PVT LTD | D26: yes | E26: Rated | F26: Bundled | G26: Rack | H26: Uncaged | I26: =IF(G26="Rack","No of Racks",(IF(G26="Space","Sq Ft","U Space"))) -> No of Racks | J26: 1 | K26: 1 | L26: =J26-K26 -> 0 | M26: =J26 -> 1 | N26: =J26-M26 -> 0 | O26: =495000/12 -> 41250 | P26: =E26 -> Rated | Q26: KVA | R26: 6 | S26: 5.5 | T26: =R26-S26 -> 0.5 | U26: 0 | V26: =IF(T26<=0,0,(IF(P26="Rated",(T26+U26)*$V$1,(T26+U26)))) -> 0.25 | W26: =IF(P26="Rated",R26*$V$1,R26) -> 3 | X26: =S26 -> 5.5 | Y26: =S26 -> 5.5 | Z26: =T26*-1 -> -0.5 | AA26: =100000/12 -> 8333.3333 | AB26: Rated | AC26: 1.8 | AG26: No of Seats | AH26: No of seats | AI26: 0 | AJ26: 0 | AK26: =AI26-AJ26 -> 0 | AL26: =AI26 -> 0 | AM26: 0 | AO26: =O26*M26 -> 41250 | AQ26: =AF26*AE26*AC26 -> 0 | AR26: =AN26*AL26 -> 0 | AT26: =SUBTOTAL(9,AO26:AS26) -> 41250
A27: L3 | B27: DC-1 | C27: Hindustan Pencil | D27: Yes | E27: Rated | F27: Bundled | G27: Rack | H27: Uncaged | I27: =IF(G27="Rack","No of Racks",(IF(G27="Space","Sq Ft","U Space"))) -> No of Racks | J27: 1 | K27: 1 | L27: =J27-K27 -> 0 | M27: =J27 -> 1 | N27: =J27-M27 -> 0 | O27: =(17500*65)/12 -> 94791.667 | P27: =E27 -> Rated | Q27: KVA | R27: 5.83 | S27: 5.8 | T27: =R27-S27 -> 0.03 | U27: 0 | V27: =IF(T27<=0,0,(IF(P27="Rated",(T27+U27)*$V$1,(T27+U27)))) -> 0.015 | W27: =IF(P27="Rated",R27*$V$1,R27) -> 2.915 | X27: =S27 -> 5.8 | Y27: =S27 -> 5.8 | Z27: =T27*-1 -> -0.03 | AB27: Rated | AC27: 1.8 | AG27: No of Seats | AH27: No of seats | AI27: 0 | AJ27: 0 | AK27: =AI27-AJ27 -> 0 | AL27: =AI27 -> 0 | AM27: 0 | AO27: =O27*M27 -> 94791.667 | AQ27: =AF27*AE27*AC27 -> 0 | AR27: =AN27*AL27 -> 0 | AT27: =SUBTOTAL(9,AO27:AS27) -> 94791.667
A28: L3 | B28: DC-1 | C28: J2 Global | D28: Yes | E28: Rated | F28: Bundled | G28: Rack | H28: Uncaged | I28: =IF(G28="Rack","No of Racks",(IF(G28="Space","Sq Ft","U Space"))) -> No of Racks | J28: 1 | K28: 1 | L28: =J28-K28 -> 0 | M28: =J28 -> 1 | N28: =J28-M28 -> 0 | O28: =1127500/12/2 -> 46979.167 | P28: =E28 -> Rated | Q28: KVA | R28: 3 | S28: 4.78 | T28: =R28-S28 -> -1.78 | U28: 0 | V28: =IF(T28<=0,0,(IF(P28="Rated",(T28+U28)*$V$1,(T28+U28)))) -> 0 | W28: =IF(P28="Rated",R28*$V$1,R28) -> 1.5 | X28: =S28 -> 4.78 | Y28: =S28 -> 4.78 | Z28: =T28*-1 -> 1.78 | AA28: =110000/12 -> 9166.6667 | AB28: Rated | AC28: 1.8 | AG28: No of Seats | AH28: No of seats | AI28: 0 | AJ28: 0 | AK28: =AI28-AJ28 -> 0 | AL28: =AI28 -> 0 | AM28: 0 | AO28: =O28*M28 -> 46979.167 | AQ28: =AF28*AE28*AC28 -> 0 | AR28: =AN28*AL28 -> 0 | AT28: =SUBTOTAL(9,AO28:AS28) -> 46979.167
A29: L3 | B29: DC-1 | C29: Ubona | D29: Yes | E29: Rated | F29: Bundled | G29: Rack | H29: Uncaged | I29: =IF(G29="Rack","No of Racks",(IF(G29="Space","Sq Ft","U Space"))) -> No of Racks | J29: 1 | K29: 1 | L29: =J29-K29 -> 0 | M29: =J29 -> 1 | N29: =J29-M29 -> 0 | O29: =649950/12 -> 54162.5 | P29: =E29 -> Rated | Q29: KVA | R29: 12 | S29: 11.14 | T29: =R29-S29 -> 0.86 | U29: 0 | V29: =IF(T29<=0,0,(IF(P29="Rated",(T29+U29)*$V$1,(T29+U29)))) -> 0.43 | W29: =IF(P29="Rated",R29*$V$1,R29) -> 6 | X29: =S29 -> 11.14 | Y29: =S29 -> 11.14 | Z29: =T29*-1 -> -0.86 | AB29: Rated | AC29: 1.8 | AG29: No of Seats | AH29: No of seats | AI29: 0 | AJ29: 0 | AK29: =AI29-AJ29 -> 0 | AL29: =AI29 -> 0 | AM29: 0 | AO29: =O29*M29 -> 54162.5 | AQ29: =AF29*AE29*AC29 -> 0 | AR29: =AN29*AL29 -> 0 | AT29: =SUBTOTAL(9,AO29:AS29) -> 54162.5
A30: L3 | B30: DC-1 | C30: Ramco | D30: Yes | E30: Rated | F30: Bundled | G30: Rack | H30: Uncaged | I30: =IF(G30="Rack","No of Racks",(IF(G30="Space","Sq Ft","U Space"))) -> No of Racks | J30: 2 | K30: 2 | L30: =J30-K30 -> 0 | M30: =J30 -> 2 | N30: =J30-M30 -> 0 | O30: =40500/12 -> 3375 | P30: =E30 -> Rated | Q30: KVA | R30: 12 | S30: 11.85 | T30: =R30-S30 -> 0.15 | U30: 0 | V30: =IF(T30<=0,0,(IF(P30="Rated",(T30+U30)*$V$1,(T30+U30)))) -> 0.075 | W30: =IF(P30="Rated",R30*$V$1,R30) -> 6 | X30: =S30 -> 11.85 | Y30: =S30 -> 11.85 | Z30: =T30*-1 -> -0.15 | AA30: =90000/12 -> 7500 | AB30: Rated | AC30: 1.8 | AG30: No of Seats | AH30: No of seats | AI30: 0 | AJ30: 0 | AK30: =AI30-AJ30 -> 0 | AL30: =AI30 -> 0 | AM30: 0 | AO30: =O30*M30 -> 6750 | AQ30: =AF30*AE30*AC30 -> 0 | AR30: =AN30*AL30 -> 0 | AT30: =SUBTOTAL(9,AO30:AS30) -> 6750
A31: L3 | B31: DC-1 | C31: Sixth Energy (NEUREOL) | D31: Yes | E31: Rated | F31: Bundled | G31: U space | H31: Uncaged | I31: =IF(G31="Rack","No of Racks",(IF(G31="Space","Sq Ft","U Space"))) -> U Space | J31: 37 | K31: 27 | L31: =J31-K31 -> 10 | M31: =J31 -> 37 | N31: =J31-M31 -> 0 | O31: =(1216313+858000)/12/2 -> 86429.708 | P31: =E31 -> Rated | Q31: KVA | R31: 14.94 | S31: 14.94 | T31: =R31-S31 -> 0 | U31: 0 | V31: =IF(T31<=0,0,(IF(P31="Rated",(T31+U31)*$V$1,(T31+U31)))) -> 0 | W31: =IF(P31="Rated",R31*$V$1,R31) -> 7.47 | X31: =S31 -> 14.94 | Y31: =S31 -> 14.94 | Z31: =T31*-1 -> 0 | AA31: =110000/12 -> 9166.6667 | AB31: Rated | AC31: 1.8 | AG31: No of Seats | AH31: No of seats | AI31: 0 | AJ31: 0 | AK31: =AI31-AJ31 -> 0 | AL31: =AI31 -> 0 | AM31: 0 | AO31: =O31*M31 -> 3197899.2 | AQ31: =AF31*AE31*AC31 -> 0 | AR31: =AN31*AL31 -> 0 | AT31: =SUBTOTAL(9,AO31:AS31) -> 3197899.2
A32: L3 | B32: DC-1 | C32: Kluber | D32: Yes | E32: Rated | F32: Bundled | G32: Rack | H32: Uncaged | I32: =IF(G32="Rack","No of Racks",(IF(G32="Space","Sq Ft","U Space"))) -> No of Racks | J32: 1 | K32: 1 | L32: =J32-K32 -> 0 | M32: =J32 -> 1 | N32: =J32-M32 -> 0 | O32: =(907600+412500)/12/2 -> 55004.167 | P32: =E32 -> Rated | Q32: KVA | R32: 12 | S32: 11.92 | T32: =R32-S32 -> 0.08 | U32: 0 | V32: =IF(T32<=0,0,(IF(P32="Rated",(T32+U32)*$V$1,(T32+U32)))) -> 0.04 | W32: =IF(P32="Rated",R32*$V$1,R32) -> 6 | X32: =S32 -> 11.92 | Y32: =S32 -> 11.92 | Z32: =T32*-1 -> -0.08 | AA32: =80000/12 -> 6666.6667 | AB32: Rated | AC32: 1.8 | AG32: No of Seats | AH32: No of seats | AI32: 0 | AJ32: 0 | AK32: =AI32-AJ32 -> 0 | AL32: =AI32 -> 0 | AM32: 0 | AO32: =O32*M32 -> 55004.167 | AQ32: =AF32*AE32*AC32 -> 0 | AR32: =AN32*AL32 -> 0 | AT32: =SUBTOTAL(9,AO32:AS32) -> 55004.167
A33: L3 | B33: DC-1 | C33: Ozonetel | D33: Yes | E33: Rated | F33: Bundled | G33: Rack | H33: Uncaged | I33: =IF(G33="Rack","No of Racks",(IF(G33="Space","Sq Ft","U Space"))) -> No of Racks | J33: 11 | K33: 11 | L33: =J33-K33 -> 0 | M33: =J33 -> 11 | N33: =J33-M33 -> 0 | O33: =561132/12 -> 46761 | P33: =E33 -> Rated | Q33: KVA | R33: 115.5 | S33: 118.33 | T33: =R33-S33 -> -2.83 | U33: 0 | V33: =IF(T33<=0,0,(IF(P33="Rated",(T33+U33)*$V$1,(T33+U33)))) -> 0 | W33: =IF(P33="Rated",R33*$V$1,R33) -> 57.75 | X33: =S33 -> 118.33 | Y33: =S33 -> 118.33 | Z33: =T33*-1 -> 2.83 | AB33: Rated | AC33: 1.8 | AG33: No of Seats | AH33: No of seats | AI33: 0 | AJ33: 0 | AK33: =AI33-AJ33 -> 0 | AL33: =AI33 -> 0 | AM33: 0 | AO33: =O33*M33 -> 514371 | AQ33: =AF33*AE33*AC33 -> 0 | AR33: =AN33*AL33 -> 0 | AT33: =SUBTOTAL(9,AO33:AS33) -> 514371
A34: L3 | B34: DC-1 | C34: SingTel | D34: Yes | E34: Rated | F34: Bundled | G34: Rack | H34: Uncaged | I34: =IF(G34="Rack","No of Racks",(IF(G34="Space","Sq Ft","U Space"))) -> No of Racks | J34: 4 | K34: 4 | L34: =J34-K34 -> 0 | M34: =J34 -> 4 | N34: =J34-M34 -> 0 | O34: =610000/12 -> 50833.333 | P34: =E34 -> Rated | Q34: KVA | R34: 12 | S34: 7.28 | T34: =R34-S34 -> 4.72 | U34: 0 | V34: =IF(T34<=0,0,(IF(P34="Rated",(T34+U34)*$V$1,(T34+U34)))) -> 2.36 | W34: =IF(P34="Rated",R34*$V$1,R34) -> 6 | X34: =S34 -> 7.28 | Y34: =S34 -> 7.28 | Z34: =T34*-1 -> -4.72 | AB34: Rated | AC34: 1.8 | AG34: No of Seats | AH34: No of seats | AI34: 0 | AJ34: 0 | AK34: =AI34-AJ34 -> 0 | AL34: =AI34 -> 0 | AM34: 0 | AO34: =O34*M34 -> 203333.33 | AQ34: =AF34*AE34*AC34 -> 0 | AR34: =AN34*AL34 -> 0 | AT34: =SUBTOTAL(9,AO34:AS34) -> 203333.33
A35: L3 | B35: DC-1 | C35: Thane Cooperative Bank | D35: Yes | E35: Rated | F35: Bundled | G35: Rack | H35: Uncaged | I35: =IF(G35="Rack","No of Racks",(IF(G35="Space","Sq Ft","U Space"))) -> No of Racks | J35: 2 | K35: 2 | L35: =J35-K35 -> 0 | M35: =J35 -> 2 | N35: =J35-M35 -> 0 | O35: =490000/12 -> 40833.333 | P35: =E35 -> Rated | Q35: KVA | R35: 10 | S35: 9.27 | T35: =R35-S35 -> 0.73 | U35: 0 | V35: =IF(T35<=0,0,(IF(P35="Rated",(T35+U35)*$V$1,(T35+U35)))) -> 0.365 | W35: =IF(P35="Rated",R35*$V$1,R35) -> 5 | X35: =S35 -> 9.27 | Y35: =S35 -> 9.27 | Z35: =T35*-1 -> -0.73 | AB35: Rated | AC35: 1.8 | AG35: No of Seats | AH35: No of seats | AI35: 0 | AJ35: 0 | AK35: =AI35-AJ35 -> 0 | AL35: =AI35 -> 0 | AM35: 0 | AO35: =O35*M35 -> 81666.667 | AQ35: =AF35*AE35*AC35 -> 0 | AR35: =AN35*AL35 -> 0 | AT35: =SUBTOTAL(9,AO35:AS35) -> 81666.667
A36: L3 | B36: DC-1 | C36: Knowlarity | D36: Yes | E36: Rated | F36: Bundled | G36: Rack | H36: Uncaged | I36: =IF(G36="Rack","No of Racks",(IF(G36="Space","Sq Ft","U Space"))) -> No of Racks | J36: 7 | K36: 7 | L36: =J36-K36 -> 0 | M36: =J36 -> 7 | N36: =J36-M36 -> 0 | O36: =498000/12 -> 41500 | P36: =E36 -> Rated | Q36: KVA | R36: 48.53 | S36: 47.9 | T36: =R36-S36 -> 0.63 | U36: 0 | V36: =IF(T36<=0,0,(IF(P36="Rated",(T36+U36)*$V$1,(T36+U36)))) -> 0.315 | W36: =IF(P36="Rated",R36*$V$1,R36) -> 24.265 | X36: =S36 -> 47.9 | Y36: =S36 -> 47.9 | Z36: =T36*-1 -> -0.63 | AA36: =110000/12 -> 9166.6667 | AB36: Rated | AC36: 1.8 | AG36: No of Seats | AH36: No of seats | AI36: 0 | AJ36: 0 | AK36: =AI36-AJ36 -> 0 | AL36: =AI36 -> 0 | AM36: 0 | AO36: =O36*M36 -> 290500 | AQ36: =AF36*AE36*AC36 -> 0 | AR36: =AN36*AL36 -> 0 | AT36: =SUBTOTAL(9,AO36:AS36) -> 290500
A37: L3 | B37: DC-1 | C37: Gradatim | D37: Yes | E37: Rated | F37: Bundled | G37: U space | H37: Uncaged | I37: =IF(G37="Rack","No of Racks",(IF(G37="Space","Sq Ft","U Space"))) -> U Space | J37: 9 | K37: 9 | L37: =J37-K37 -> 0 | M37: =J37 -> 9 | N37: =J37-M37 -> 0 | O37: =32000/12 -> 2666.6667 | P37: =E37 -> Rated | Q37: KVA | R37: 8.06 | S37: 3.9 | T37: =R37-S37 -> 4.16 | U37: 0 | V37: =IF(T37<=0,0,(IF(P37="Rated",(T37+U37)*$V$1,(T37+U37)))) -> 2.08 | W37: =IF(P37="Rated",R37*$V$1,R37) -> 4.03 | X37: =S37 -> 3.9 | Y37: =S37 -> 3.9 | Z37: =T37*-1 -> -4.16 | AA37: 0 | AB37: Rated | AC37: 1.8 | AG37: No of Seats | AH37: No of seats | AI37: 0 | AJ37: 0 | AK37: =AI37-AJ37 -> 0 | AL37: =AI37 -> 0 | AM37: 0 | AO37: =O37*M37 -> 24000 | AQ37: =AF37*AE37*AC37 -> 0 | AR37: =AN37*AL37 -> 0 | AT37: =SUBTOTAL(9,AO37:AS37) -> 24000
A38: L3 | B38: DC-1 | C38: INFIBEAM AVENUES LIMITED | D38: Yes | E38: Rated | F38: Bundled | G38: Rack | H38: Uncaged | I38: =IF(G38="Rack","No of Racks",(IF(G38="Space","Sq Ft","U Space"))) -> No of Racks | J38: 2 | K38: 2 | L38: =J38-K38 -> 0 | M38: =J38 -> 2 | N38: =J38-M38 -> 0 | O38: =(510500+365000)/2/12 -> 36479.167 | P38: =E38 -> Rated | Q38: KVA | R38: 21 | S38: 23.3 | T38: =R38-S38 -> -2.3 | U38: 0 | V38: =IF(T38<=0,0,(IF(P38="Rated",(T38+U38)*$V$1,(T38+U38)))) -> 0 | W38: =IF(P38="Rated",R38*$V$1,R38) -> 10.5 | X38: =S38 -> 23.3 | Y38: =S38 -> 23.3 | Z38: =T38*-1 -> 2.3 | AA38: =85000/12 -> 7083.3333 | AB38: Rated | AC38: 1.8 | AG38: No of Seats | AH38: No of seats | AI38: 0 | AJ38: 0 | AK38: =AI38-AJ38 -> 0 | AL38: =AI38 -> 0 | AM38: 0 | AO38: =O38*M38 -> 72958.333 | AQ38: =AF38*AE38*AC38 -> 0 | AR38: =AN38*AL38 -> 0 | AT38: =SUBTOTAL(9,AO38:AS38) -> 72958.333
A39: L3 | B39: DC-1 | C39: Maximus Infoware | D39: Yes | E39: Rated | F39: Bundled | G39: U space | H39: Uncaged | I39: =IF(G39="Rack","No of Racks",(IF(G39="Space","Sq Ft","U Space"))) -> U Space | J39: 8 | K39: 5 | L39: =J39-K39 -> 3 | M39: =J39 -> 8 | N39: =J39-M39 -> 0 | O39: =550000/12 -> 45833.333 | P39: =E39 -> Rated | Q39: KVA | R39: 1.75 | S39: 1.6 | T39: =R39-S39 -> 0.15 | U39: 0 | V39: =IF(T39<=0,0,(IF(P39="Rated",(T39+U39)*$V$1,(T39+U39)))) -> 0.075 | W39: =IF(P39="Rated",R39*$V$1,R39) -> 0.875 | X39: =S39 -> 1.6 | Y39: =S39 -> 1.6 | Z39: =T39*-1 -> -0.15 | AA39: =90000/12 -> 7500 | AB39: Rated | AC39: 1.8 | AG39: No of Seats | AH39: No of seats | AI39: 0 | AJ39: 0 | AK39: =AI39-AJ39 -> 0 | AL39: =AI39 -> 0 | AM39: 0
A40: L3 | B40: DC-1 | C40: Avenue Ecommerce | D40: Yes | E40: Rated | F40: Bundled | G40: Rack | H40: Uncaged | I40: =IF(G40="Rack","No of Racks",(IF(G40="Space","Sq Ft","U Space"))) -> No of Racks | J40: 4 | K40: 4 | L40: =J40-K40 -> 0 | M40: =J40 -> 4 | N40: =J40-M40 -> 0 | O40: =600000/12 -> 50000 | P40: =E40 -> Rated | Q40: KVA | R40: 33 | S40: 28.03 | T40: =R40-S40 -> 4.97 | U40: 0 | V40: =IF(T40<=0,0,(IF(P40="Rated",(T40+U40)*$V$1,(T40+U40)))) -> 2.485 | W40: =IF(P40="Rated",R40*$V$1,R40) -> 16.5 | X40: =S40 -> 28.03 | Y40: =S40 -> 28.03 | Z40: =T40*-1 -> -4.97 | AA40: =90000/12 -> 7500 | AB40: Rated | AC40: 1.8 | AG40: No of Seats | AH40: No of seats | AI40: 0 | AJ40: 0 | AK40: =AI40-AJ40 -> 0 | AL40: =AI40 -> 0 | AM40: 0
...

Sheet Disconnection details
T1: Divisification | V1: 0.5 | W1: Rated to Consumed | Z1: =#REF! -> #REF! | AB1: Actual PUE | AC1: =#REF! -> #REF! | AD1: Actual Unit Rate: | AE1: =#REF! -> #REF! | AF1: =+AC1*(AE1*(30.5*24-AH1)+AH1*20) -> #REF! | AG1: Genset Hr/Mo | AH1: 5
E2: Billing Model | G2: Space | P2: Power Capacity | AB2: Power Usage | AG2: Seating Space | AO2: Revenue (Monthly ) | AV2: Contract Information
A3: Floor | B3: Floor / Module | C3: Customer Name | D3: RHS/SH | E3: Power Subscription Model (Rated/Subscribed) | F3: Power Usage Model (Bundled / Metered) | G3: Subscription Mode | H3: Caged /Uncaged | I3: UoM | J3: Subscription | K3: In Use | L3: Yet to be given/ | M3: Billed | N3: Reserved Capacity if any (Non-Billable) | O3: Per Unit rate (MRC) | P3: Subscription Model | Q3: UoM | R3: Total Capacity Purchased | S3: Capacity in Use | T3: Capacity to be given | U3: Reserved Capacity if any | V3: Subscribed Capacity to be given in KW | W3: "Allocated" Capacity in KW | X3: DC NW Infra | Y3: Usage in KW | Z3: Billable Additional Capacity | AA3: Additional Capacity Charges (MRC) | AB3: Usage Model | AC3: Multiplier | AD3: Unit rate Model (Fixed/Variable) | AE3: Unit Rate (per KW-HR) | AF3: No Of Units (KW-HR/ Month | AG3: Subscription Model | AH3: UoM | AI3: Subscription | AJ3: In Use | AK3: Yet to be given | AL3: Billed | AM3: Reserved Capacity if any | AN3: Per Unit rate | AO3: Space revenue including capacity | AP3: Additional Capacity Revenue | AQ3: Power Usage revenue | AR3: Seating Space | AS3: Any Other Items | AT3: Total Revenue | AU3: Billing Frequency | AV3: Sales Order ref No | AW3: Contract Start Date | AX3: Term of Contract (No of Years) | AY3: Current Expiry Date | AZ3: Remarks if any | BA3: Cross connect
A4: L3 | B4: DC-2 | C4: BESCOM | D4: yes | E4: Rated | F4: Bundled | G4: Rack | H4: Caged | I4: =IF(G4="Rack","No of Racks",(IF(G4="Space","Sq Ft","U Space"))) -> No of Racks | J4: 33 | K4: 33 | L4: =J4-K4 -> 0 | M4: =J4 -> 33 | N4: 0
A5: L3 | B5: DC-2 | C5: Timesofmoney(Unimoni Enterprise Solutions Pvt. Ltd) | D5: yes | E5: Rated | F5: Bundled | G5: Rack | H5: Uncaged | I5: =IF(G5="Rack","No of Racks",(IF(G5="Space","Sq Ft","U Space"))) -> No of Racks | J5: 2 | K5: 2 | L5: =J5-K5 -> 0 | M5: =J5 -> 2 | N5: 0
A6: L3 | B6: DC-1 | C6: TechM WAAS(ING) | D6: yes | E6: Rated | F6: Bundled | G6: Rack | H6: Uncaged | I6: =IF(G6="Rack","No of Racks",(IF(G6="Space","Sq Ft","U Space"))) -> No of Racks | J6: 1 | K6: 1 | L6: =J6-K6 -> 0 | M6: =J6 -> 1 | N6: 0
A7: L3 | B7: DC-3 | C7: Shapoorji Pallonji | D7: yes | E7: Rated | F7: Bundled | G7: Rack | H7: Uncaged | I7: =IF(G7="Rack","No of Racks",(IF(G7="Space","Sq Ft","U Space"))) -> No of Racks | J7: 3 | K7: 3 | L7: =J7-K7 -> 0 | M7: =J7 -> 3 | N7: 0
A8: L3 | B8: DC-1 | C8: FedBank | D8: yes | E8: Rated | F8: Bundled | G8: Rack | H8: Uncaged | I8: =IF(G8="Rack","No of Racks",(IF(G8="Space","Sq Ft","U Space"))) -> No of Racks | J8: 1 | K8: 1 | L8: =J8-K8 -> 0 | M8: =J8 -> 1 | N8: 0
A9: L3 | B9: DC-2 | C9: Sungard | D9: yes | E9: Subscribed | F9: Metered | G9: Rack | H9: Uncaged | I9: =IF(G9="Rack","No of Racks",(IF(G9="Space","Sq Ft","U Space"))) -> No of Racks | J9: 2 | K9: 2 | L9: =J9-K9 -> 0 | M9: =J9 -> 2 | N9: 0
A10: L3 | B10: DC-1 | C10: Star union daichi | D10: yes | E10: Subscribed | F10: Metered | G10: Rack | H10: Caged | I10: =IF(G10="Rack","No of Racks",(IF(G10="Space","Sq Ft","U Space"))) -> No of Racks | J10: 5 | K10: 5 | L10: =J10-K10 -> 0 | M10: =J10 -> 5 | N10: 0
A11: L3 | B11: DC-3 | C11: India Post payment bank Ltd | D11: No | E11: Subscribed | F11: Metered | G11: Rack | H11: Caged | I11: =IF(G11="Rack","No of Racks",(IF(G11="Space","Sq Ft","U Space"))) -> No of Racks | J11: 19 | K11: 19 | L11: =J11-K11 -> 0 | M11: =J11 -> 19 | N11: =J11-M11 -> 0 | O11: =6303333/12/19 -> 27646.197 | P11: =E11 -> Subscribed | Q11: KVA | R11: 58 | S11: 27.35 | T11: =R11-S11 -> 30.65 | U11: 0 | V11: =IF(T11<=0,0,(IF(P11="Rated",(T11+U11)*$V$1,(T11+U11)))) -> 30.65 | W11: =IF(P11="Rated",R11*$V$1,R11) -> 58 | X11: =S11 -> 27.35 | Y11: =S11 -> 27.35 | Z11: =T11*-1 -> -30.65 | AB11: Metered | AC11: 1 | AD11: Fixed | AE11: 15 | AF11: 37695.3 | AG11: No of Seats | AH11: No of seats | AI11: 6 | AJ11: 6 | AK11: 0 | AL11: =AI11 -> 6 | AM11: 0 | AN11: =(100000/12) -> 8333.3333 | AO11: =O11*M11 -> 525277.75 | AQ11: =AF11*AE11*AC11 -> 565429.5 | AR11: =AN11*AL11 -> 50000 | AT11: =SUBTOTAL(9,AO11:AS11) -> 1140707.2 | BB11: Disconnected on 15 March 2025
A12: L3 | B12: DC-1 | C12: BAJAJ FINANCIAL SECURITIES LTD | D12: Yes | E12: Rated | F12: Bundled | G12: U space | H12: Uncaged | I12: =IF(G12="Rack","No of Racks",(IF(G12="Space","Sq Ft","U Space"))) -> U Space | J12: 2 | K12: 5 | L12: =J12-K12 -> -3 | M12: 4 | N12: =J12-M12 -> -2 | O12: =(39750+39750/4)/12 -> 4140.625 | P12: Rated | Q12: KVA | R12: 0.5 | S12: 0.186 | T12: =R12-S12 -> 0.314 | U12: 0 | V12: =IF(T12<=0,0,(IF(P12="Rated",(T12+U12)*'[1]Customer details'!$V$1,(T12+U12)))) -> 0 | W12: =IF(P12="Rated",R12*'[1]Customer details'!$V$1,R12) -> 0 | X12: =S12 -> 0.186 | Y12: =S12 -> 0.186 | Z12: =T12*-1 -> -0.314 | AB12: Rated | AC12: 1.8 | AG12: No of Seats | AH12: No of seats | AI12: 0 | AJ12: 0 | AK12: 0 | AL12: =AI12 -> 0 | AM12: 0
A13: L3 | B13: DC-1 | C13: UCO BANK 2 - Temp | D13: Yes | E13: Rated | F13: Bundled | G13: Rack | H13: Uncaged | I13: =IF(G13="Rack","No of Racks",(IF(G13="Space","Sq Ft","U Space"))) -> No of Racks | J13: 4 | K13: 4 | L13: =J13-K13 -> 0 | M13: 4 | N13: =J13-M13 -> 0 | P13: Rated | Q13: KVA | R13: 29 | S13: 28.96 | T13: =R13-S13 -> 0.04 | U13: 0 | V13: =IF(T13<=0,0,(IF(P13="Rated",(T13+U13)*'[1]Customer details'!$V$1,(T13+U13)))) -> 0 | W13: =IF(P13="Rated",R13*'[1]Customer details'!$V$1,R13) -> 0 | X13: =S13 -> 28.96 | Y13: =S13 -> 28.96 | Z13: =T13*-1 -> -0.04 | AB13: Rated | AC13: 1.8 | AG13: No of Seats | AH13: No of seats | AI13: 1 | AJ13: 1 | AK13: 0 | AL13: =AI13 -> 1 | AM13: 0
A14: L3 | B14: DC-1 | C14: kfintek | D14: yes | E14: Subscribed | F14: Metered | G14: Rack | H14: Uncaged | I14: =IF(G14="Rack","No of Racks",(IF(G14="Space","Sq Ft","U Space"))) -> No of Racks | J14: 10 | K14: 10 | L14: =J14-K14 -> 0 | M14: =J14 -> 10 | N14: =J14-M14 -> 0 | P14: =E14 -> Subscribed | Q14: KW | R14: 30 | S14: 17.35 | T14: =R14-S14 -> 12.65 | U14: 0 | V14: =IF(T14<=0,0,(IF(P14="Rated",(T14+U14)*$V$1,(T14+U14)))) -> 12.65 | W14: =IF(P14="Rated",R14*$V$1,R14) -> 30 | X14: =S14 -> 17.35 | Y14: =S14 -> 17.35 | Z14: =T14*-1 -> -12.65 | AB14: Metered | AC14: 1.8 | AF14: 0 | AG14: No of Seats | AH14: No of seats | AI14: 0 | AJ14: 0 | AK14: =AI14-AJ14 -> 0 | AL14: =AI14 -> 0 | AM14: 0 | AO14: =O14*M14 -> 0 | AQ14: =AF14*AE14*AC14 -> 0 | AR14: =AN14*AL14 -> 0 | AT14: =SUBTOTAL(9,AO14:AS14) -> 0
A15: L3 | B15: DC-1 | C15: TECHNO TRUST SOLUTIONS | D15: Yes | E15: Rated | F15: Bundled | G15: Rack | H15: Uncaged | I15: =IF(G15="Rack","No of Racks",(IF(G15="Space","Sq Ft","U Space"))) -> No of Racks | J15: 1 | K15: 1 | L15: =J15-K15 -> 0 | M15: =J15 -> 1 | N15: =J15-M15 -> 0 | O15: =30000/12 -> 2500 | P15: =E15 -> Rated | Q15: KVA | R15: 4 | S15: 6.2 | T15: =R15-S15 -> -2.2 | U15: 0 | V15: =IF(T15<=0,0,(IF(P15="Rated",(T15+U15)*'[2]Customer details'!$V$1,(T15+U15)))) -> 0 | W15: =IF(P15="Rated",R15*'[2]Customer details'!$V$1,R15) -> 2 | X15: =S15 -> 6.2 | Y15: =S15 -> 6.2 | Z15: =T15*-1 -> 2.2 | AA15: =90000/12 -> 7500 | AB15: Rated | AC15: 1.8 | AG15: No of Seats | AH15: No of seats | AI15: 1 | AJ15: 1 | AK15: =AI15-AJ15 -> 0 | AL15: =AI15 -> 1 | AM15: 0 | AO15: =O15*M15 -> 2500 | AQ15: =AF15*AE15*AC15 -> 0 | AR15: =AN15*AL15 -> 0 | AT15: =SUBTOTAL(9,AO15:AS15) -> 2500
A16: L3 | B16: DC-1 | C16: ASB International | D16: Yes | E16: Rated | F16: Bundled | G16: U space | H16: Uncaged | I16: =IF(G16="Rack","No of Racks",(IF(G16="Space","Sq Ft","U Space"))) -> U Space | J16: 4 | K16: 4 | L16: =J16-K16 -> 0 | M16: =J16 -> 4 | N16: =J16-M16 -> 0 | O16: =360000/21/12 -> 1428.5714 | P16: =E16 -> Rated | Q16: KVA | R16: 1 | S16: 0.847 | T16: =R16-S16 -> 0.153 | U16: 0 | V16: =IF(T16<=0,0,(IF(P16="Rated",(T16+U16)*'Customer details'!$V$1,(T16+U16)))) -> 0.0765 | W16: =IF(P16="Rated",R16*'Customer details'!$V$1,R16) -> 0.5 | X16: =S16 -> 0.847 | Y16: =S16 -> 0.847 | Z16: =T16*-1 -> -0.153 | AA16: =90000/12 -> 7500 | AB16: Rated | AC16: 1.8 | AG16: No of Seats | AH16: No of seats | AI16: 0 | AJ16: 0 | AK16: =AI16-AJ16 -> 0 | AL16: =AI16 -> 0 | AM16: 0 | AO16: =O16*M16 -> 5714.2857 | AQ16: =AF16*AE16*AC16 -> 0 | AR16: =AN16*AL16 -> 0 | AT16: =SUBTOTAL(9,AO16:AS16) -> 5714.2857
A17: L3 | B17: DC-1 | C17: Que Processing Service Ltd | D17: Yes | E17: Rated | F17: Bundled | G17: Rack | H17: Uncaged | I17: =IF(G17="Rack","No of Racks",(IF(G17="Space","Sq Ft","U Space"))) -> No of Racks | J17: 1 | K17: 1 | L17: =J17-K17 -> 0 | M17: =J17 -> 1 | N17: =J17-M17 -> 0 | P17: =E17 -> Rated | Q17: KVA | R17: 2.77 | S17: 0.06 | T17: =R17-S17 -> 2.71 | U17: 0 | V17: =IF(T17<=0,0,(IF(P17="Rated",(T17+U17)*'Customer details'!$V$1,(T17+U17)))) -> 1.355 | W17: =IF(P17="Rated",R17*'Customer details'!$V$1,R17) -> 1.385 | X17: =S17 -> 0.06 | Y17: =S17 -> 0.06 | Z17: =T17*-1 -> -2.71 | AB17: Rated | AC17: 1.8 | AG17: No of Seats | AH17: No of seats | AI17: 0 | AJ17: 0 | AK17: =AI17-AJ17 -> 0 | AL17: =AI17 -> 0 | AM17: 0
A18: L3 | B18: DC-1 | C18: SH Kelkar | D18: Yes | E18: Rated | F18: Bundled | G18: Rack | H18: Uncaged | I18: =IF(G18="Rack","No of Racks",(IF(G18="Space","Sq Ft","U Space"))) -> No of Racks | J18: 1 | K18: 1 | L18: =J18-K18 -> 0 | M18: =J18 -> 1 | N18: =J18-M18 -> 0 | O18: =634575/17/12 -> 3110.6618 | P18: =E18 -> Rated | Q18: KVA | R18: 3 | S18: 2.25 | T18: =R18-S18 -> 0.75 | U18: 0 | V18: =IF(T18<=0,0,(IF(P18="Rated",(T18+U18)*'Customer details'!$V$1,(T18+U18)))) -> 0.375 | W18: =IF(P18="Rated",R18*'Customer details'!$V$1,R18) -> 1.5 | X18: =S18 -> 2.25 | Y18: =S18 -> 2.25 | Z18: =T18*-1 -> -0.75 | AA18: =95000/12 -> 7916.6667 | AB18: Rated | AC18: 1.8 | AG18: No of Seats | AH18: No of seats | AI18: 0 | AJ18: 0 | AK18: =AI18-AJ18 -> 0 | AL18: =AI18 -> 0 | AM18: 0 | AO18: =O18*M18 -> 3110.6618 | AQ18: =AF18*AE18*AC18 -> 0 | AR18: =AN18*AL18 -> 0 | AT18: =SUBTOTAL(9,AO18:AS18) -> 3110.6618
A19: L3 | B19: DC-1 | C19: AKSHAYAPATRA FOUNDATION | D19: Yes | E19: Rated | F19: Bundled | G19: Rack | H19: Uncaged | I19: =IF(G19="Rack","No of Racks",(IF(G19="Space","Sq Ft","U Space"))) -> No of Racks | J19: 1 | K19: 1 | L19: =J19-K19 -> 0 | M19: =J19 -> 1 | N19: =J19-M19 -> 0 | P19: =E19 -> Rated | Q19: KVA | R19: 3 | S19: 4.06 | T19: =R19-S19 -> -1.06 | U19: 0 | V19: =IF(T19<=0,0,(IF(P19="Rated",(T19+U19)*'Customer details'!$V$1,(T19+U19)))) -> 0 | W19: =IF(P19="Rated",R19*'Customer details'!$V$1,R19) -> 1.5 | X19: =S19 -> 4.06 | Y19: =S19 -> 4.06 | Z19: =T19*-1 -> 1.06 | AB19: Rated | AC19: 1.8 | AG19: No of Seats | AH19: No of seats | AI19: 0 | AJ19: 0 | AK19: =AI19-AJ19 -> 0 | AL19: =AI19 -> 0 | AM19: 0
A20: L3 | B20: DC-1 | C20: DEEPIJA TELECOM PRIVATE LIMITED | D20: yes | E20: Rated | F20: Bundled | G20: Rack | H20: Uncaged | I20: =IF(G20="Rack","No of Racks",(IF(G20="Space","Sq Ft","U Space"))) -> No of Racks | J20: 1 | K20: 1 | L20: =J20-K20 -> 0 | M20: =J20 -> 1 | N20: =J20-M20 -> 0 | P20: =E20 -> Rated | Q20: KVA | R20: 3 | S20: 2.99 | T20: =R20-S20 -> 0.01 | U20: 0 | V20: =IF(T20<=0,0,(IF(P20="Rated",(T20+U20)*'Customer details'!$V$1,(T20+U20)))) -> 0.005 | W20: =IF(P20="Rated",R20*'Customer details'!$V$1,R20) -> 1.5 | X20: =S20 -> 2.99 | Y20: =S20 -> 2.99 | Z20: =T20*-1 -> -0.01 | AA20: =98000/12 -> 8166.6667 | AB20: Rated | AC20: 1.8 | AG20: No of Seats | AH20: no of seats | AI20: 0 | AJ20: 0 | AK20: =AI20-AJ20 -> 0 | AL20: =AI20 -> 0 | AM20: 0
A21: L3 | B21: DC-1 | C21: CITO INFOTECH PRIVATE LIMITED | D21: yes | E21: Rated | F21: Bundled | G21: U space | H21: Uncaged | I21: =IF(G21="Rack","No of Racks",(IF(G21="Space","Sq Ft","U Space"))) -> U Space | J21: 3 | K21: 3 | L21: =J21-K21 -> 0 | M21: =J21 -> 3 | N21: =J21-M21 -> 0 | P21: =E21 -> Rated | Q21: KVA | R21: 0.6 | S21: 0.893 | T21: =R21-S21 -> -0.293 | U21: 0 | V21: =IF(T21<=0,0,(IF(P21="Rated",(T21+U21)*'Customer details'!$V$1,(T21+U21)))) -> 0 | W21: =IF(P21="Rated",R21*'Customer details'!$V$1,R21) -> 0.3 | X21: =S21 -> 0.893 | Y21: =S21 -> 0.893 | Z21: =T21*-1 -> 0.293 | AB21: Rated | AC21: 1.8 | AG21: No of Seats | AH21: No of seats | AI21: 0 | AJ21: 0 | AK21: =AI21-AJ21 -> 0 | AL21: =AI21 -> 0 | AM21: 0
